2023-09-23 13:32:50,604 - celery - ERROR - Task failed!
2023-09-23 13:32:50,604 - celery.app.trace - ERROR - Task cubeseed.notifications.tasks.send_email_notification[3f4fb105-3f59-4d87-9e58-b9bf2cbbc4ee] raised unexpected: AttributeError("'list' object has no attribute 'email'")
Traceback (most recent call last):
  File "/home/niklaus/Full-Stack/cubeseed-backend/.venv/lib/python3.10/site-packages/celery/app/trace.py", line 477, in trace_task
    R = retval = fun(*args, **kwargs)
  File "/home/niklaus/Full-Stack/cubeseed-backend/.venv/lib/python3.10/site-packages/celery/app/trace.py", line 760, in __protected_call__
    return self.run(*args, **kwargs)
  File "/home/niklaus/Full-Stack/cubeseed-backend/cubeseed/notifications/tasks.py", line 136, in send_email_notification
    "support_email": sender.email,
AttributeError: 'list' object has no attribute 'email'
2023-09-23 13:33:27,165 - celery - ERROR - Task failed!
2023-09-23 13:33:27,166 - celery.app.trace - ERROR - Task cubeseed.notifications.tasks.send_email_notification[99a89453-3fdd-445c-82ae-68a2ccbc3d12] raised unexpected: AttributeError("'list' object has no attribute 'email'")
Traceback (most recent call last):
  File "/home/niklaus/Full-Stack/cubeseed-backend/.venv/lib/python3.10/site-packages/celery/app/trace.py", line 477, in trace_task
    R = retval = fun(*args, **kwargs)
  File "/home/niklaus/Full-Stack/cubeseed-backend/.venv/lib/python3.10/site-packages/celery/app/trace.py", line 760, in __protected_call__
    return self.run(*args, **kwargs)
  File "/home/niklaus/Full-Stack/cubeseed-backend/cubeseed/notifications/tasks.py", line 136, in send_email_notification
    "support_email": FROM_EMAIL,
AttributeError: 'list' object has no attribute 'email'
2023-09-23 17:20:50,071 [INFO] django.utils.autoreload: Watching for file changes with StatReloader
2023-09-23 17:20:56,777 [INFO] django.utils.autoreload: /home/niklaus/Full-Stack/cubeseed-backend/cubeseed/settings.py changed, reloading.
